Workbook

Sheet Cover
B2: N-able, Inc. (NASDAQ: NABL)
B3: SaaS Go-to-Market Metrics and Capacity Model
B4: FY2025 actuals | FY2026 plan capacity test | Built August 2026
B7: THE QUESTION
B8: N-able ended FY2025 with $539.7M in ARR and originally guided to $581M–$586M for FY2026.
B9: This model tests where the additional ARR needed to come from and whether estimated sales capacity could support the plan.
B11: BOTTOM LINE
B12: The plan had little room for error. Growth depended heavily on existing partners, especially larger ones. Modeled sales capacity covered 91% of the original plan, and the base case came in $0.6M below the guidance minimum.
B15: KEY METRICS
B16: EXPANSION SHARE OF FY2025 GROSS NEW ARR | C16: SHARE OF FY2025 ARR GROWTH FROM >$50K PARTNERS | D16: NEW LOGO ARR GROWTH REQUIRED TO MEET GUIDANCE | E16: MODELED SALES CAPACITY COVERAGE | F16: BASE CASE VS ORIGINAL GUIDANCE LOW
B17: ='ARR Bridge'!B26 -> 0.73446328 | C17: =Segmentation!C21 -> 0.94414211 | D17: ='ARR Bridge'!C43 -> 0.21872517 | E17: ='GTM Capacity'!B53 -> 0.91070067 | F17: =Scenarios!C26 -> -0.64268
B18: New logo contributed 26.6% | C18: $50K+ partners represented 61% of ARR | D18: Required to reach the $583.5M midpoint | E18: $89.0M capacity vs $97.8M required | F18: $580.4M base case vs $581.0M floor
B20: NOTES
B21: Reported = disclosed by N-able | Derived = calculated from reported data | Modeled = estimated using stated assumptions
B23: SOURCES
B24: [1] Q4/FY2025 results · 8-K Ex-99.1, 18 Feb 2026 · SEC EDGAR
B25: [2] Q4 FY2025 earnings call transcript · 19 Feb 2026
B26: [3] Q4 FY2024 earnings call transcript · Feb 2025
B27: [4] Q1 FY2026 results · 6 May 2026
B28: [5] Q2 FY2026 earnings call transcript · 17 Aug 2026
B29: [6] Q3 FY2025 results · Nov 2025

Sheet Summary
A1: N-able, Inc. (NASDAQ: NABL) | SaaS Go-to-Market Metrics and Capacity Model
A2: Tab 8 | Output Summary
A3: All figures link from the underlying tabs; no calculations are performed here. $ in millions unless noted
A5: KEY METRICS
B6: EXPANSION SHARE OF FY2025 GROSS NEW ARR | C6: SHARE OF FY2025 ARR GROWTH FROM >$50K PARTNERS | D6: NEW LOGO ARR GROWTH REQUIRED TO MEET GUIDANCE | E6: MODELED SALES CAPACITY COVERAGE | F6: BASE CASE VS ORIGINAL GUIDANCE LOW
B7: ='ARR Bridge'!B26 -> 0.73446328 | C7: =Segmentation!C21 -> 0.94414211 | D7: ='ARR Bridge'!C43 -> 0.21872517 | E7: ='GTM Capacity'!B53 -> 0.91070067 | F7: =Scenarios!C26 -> -0.64268
A9: 1. KEY OUTPUTS
A10: FY2025: the growth came from the installed base
A11: FY2025 ending ARR (reported) | B11: =Actuals!E7 -> 539.7
A12: FY2025 gross new ARR (derived) | B12: ='ARR Bridge'!B23 -> 85.314
A13: of which new logo | B13: ='ARR Bridge'!B16 -> 22.654
A14: of which expansion | B14: ='ARR Bridge'!B15 -> 62.66
A15: FY2025 gross churn and downgrade (derived) | B15: =-'ARR Bridge'!B14 -> 48.2
A16: Expansion share of gross new ARR | B16: ='ARR Bridge'!B26 -> 0.73446328
A18: The base it came from was narrowing
A19: Partners with ARR > $50K, FY2025 | B19: =Actuals!E10 -> 2671
A20: Share of ARR held by that cohort | B20: =Actuals!E11 -> 0.61
A21: Share of FY2025 ARR growth from that cohort | B21: =Segmentation!C21 -> 0.94414211
A22: Long tail ARR change, FY2025 to Q2 FY2026 | B22: =Segmentation!D23 -> -9.018
A24: FY2026 GUIDANCE REQUIREMENT VS MODELED CAPACITY
A25: Required gross new ARR at guidance mid | B25: ='ARR Bridge'!C39 -> 97.77
A26: Required new logo growth vs FY2025 | B26: ='ARR Bridge'!C43 -> 0.21872517
A27: Ramped QCR-years required | B27: ='GTM Capacity'!B24 -> 309.00243
A28: Ramped QCR-years fielded under the hiring plan | B28: ='GTM Capacity'!B55 -> 281.40872
A29: Capacity coverage of the plan | B29: ='GTM Capacity'!B53 -> 0.91070067
A30: Capacity gap | B30: ='GTM Capacity'!B52 -> -8.7307958
A31: Fix: ramped reps needed on 1 January | B31: ='GTM Capacity'!B66 -> 27.593711
A32: or: productivity uplift per rep instead | B32: ='GTM Capacity'!B69 -> 0.098055637
A33: Required qualified pipeline | B33: ='GTM Capacity'!B28 -> 342.195
A34: Change in implied S&M intensity vs FY2025 | B34: ='GTM Capacity'!B79 -> 72.967927
A36: What the drivers deliver, against both floors
A37: Base case FY2026 ending ARR | B37: =Scenarios!C19 -> 580.35732
A38: Gap to original guidance low ($581M) | B38: =Scenarios!C26 -> -0.64268
A39: Downside case FY2026 ending ARR | B39: =Scenarios!B19 -> 559.4595
A40: Revised guidance low, issued 6 Aug 2026 | B40: =Actuals!C35 -> 562
A41: Downside case vs revised guidance low | B41: =Scenarios!B30 -> -2.5405
A43: 2. FINDINGS
A44: 1. Expansion contributed 73.4% of FY2025 gross new ARR; new logo contributed 26.6%
A45: 2. Partners above $50K generated 94.4% of FY2025 ARR growth and represented 63% of ARR by Q2 FY2026
A46: 3. At the original guidance midpoint, new-logo ARR needed to grow 21.9% if expansion remained at the FY2025 rate
...

Sheet Assumptions
A1: N-able, Inc. (NASDAQ: NABL) | SaaS Go-to-Market Metrics and Capacity Model
A2: Tab 2 | Assumptions and Drivers
A3: $ in millions unless noted. Blue font = analyst input | Black = formula | Green = linked cell | Yellow fill = key input
A5: 1. SCENARIO SELECTION
A6: Active scenario (1 = Downside, 2 = Base, 3 = Upside) | B6: 2
A7: Active scenario name | B7: =INDEX($B$11:$B$13,$B$6) -> Base
A9: Scenario library
A10: # | B10: Scenario | C10: Gross retention (GRR) | D10: New logo ARR growth vs FY25 | E10: Expansion rate uplift vs FY25 | F10: FX impact on ending ARR ($mm) | G10: Quota attainment
A11: 1 | B11: Downside | C11: 0.888 | D11: -0.05 | E11: -0.012 | F11: -5 | G11: 0.78
A12: 2 | B12: Base | C12: 0.9 | D12: 0.08 | E12: 0 | F12: 0 | G12: 0.85
A13: 3 | B13: Upside | C13: 0.915 | D13: 0.2 | E13: 0.02 | F13: 5 | G13: 0.92
A15: 2. SELECTED SCENARIO DRIVERS (resolve off the scenario switch above)
A16: Gross revenue retention (GRR), FY2026E | B16: =INDEX($C$11:$C$13,$B$6) -> 0.9
A17: New logo ARR growth vs FY2025 | B17: =INDEX($D$11:$D$13,$B$6) -> 0.08
A18: Expansion rate uplift vs FY2025 (pts of beginning ARR) | B18: =INDEX($E$11:$E$13,$B$6) -> 0
A19: FX impact on FY2026 ending ARR ($mm) | B19: =INDEX($F$11:$F$13,$B$6) -> 0
A20: Quota attainment, FY2026E | B20: =INDEX($G$11:$G$13,$B$6) -> 0.85
A22: 3. ARR BRIDGE INPUTS
A23: FY2025 gross revenue retention (GRR) | B23: 0.9
A25: 4. SALES CAPACITY INPUTS
A26: Quota-carrying compensation as % of total S&M | B26: 0.4
A27: Fully loaded cost per quota-carrying rep ($000) | B27: 235
A28: FY2025 quota attainment | B28: 0.85
A29: Beginning headcount as % of FY2025 average QCRs | B29: 1.04
A30: Ramp: productivity in months 1-3 | B30: 0
A31: Ramp: productivity in months 4-6 | B31: 0.5
A32: Ramp: productivity in months 7+ | B32: 1
A33: Annual quota-carrying rep attrition | B33: 0.18
A34: Required pipeline coverage ratio | B34: 3.5
A35: FY2026 quota inflation on fully-ramped quota | B35: 0.03
A36: 5. SENSITIVITY GRID AXES (used on the Scenarios tab)
A37: GRR axis (rows) | B37: 0.87 | C37: 0.885 | D37: 0.9 | E37: 0.915 | F37: 0.93
A38: New logo ARR growth axis (columns) | B38: -0.2 | C38: -0.1 | D38: 0 | E38: 0.1 | F38: 0.2

Sheet Actuals
A1: N-able, Inc. (NASDAQ: NABL) | SaaS Go-to-Market Metrics and Capacity Model
A2: Tab 3 | Reported Actuals and Guidance
A3: $ in millions unless noted. Blue font = reported figure | Black = calculated value | Sources in column H. FY figures are full-year; Q1/Q2 revenue and EBITDA are quarterly
A5: 1. OPERATING AND FINANCIAL METRICS
A6: Metric | B6: Unit | C6: FY2023A | D6: FY2024A | E6: FY2025A | F6: Q1 FY2026A | G6: Q2 FY2026A | H6: Source
A7: Total ARR (period end) | B7: $mm | C7: =D7/(1+D8) -> 442.20183 | D7: 482 | E7: 539.7 | F7: 548 | G7: 544.5 | H7: FY24, FY25 [1][3]; Q1 [4]; Q2 [5]. FY2023 DERIVED from FY2024 reported growth
A8: ARR growth, YoY reported | B8: % | D8: 0.09 | E8: 0.119 | F8: 0.112 | H8: [1][3][4]
A9: ARR growth, YoY constant currency | B9: % | D9: 0.1 | E9: 0.077 | F9: 0.079 | G9: 0.057 | H9: [1][3][4][5]
A10: Partners with ARR > $50,000 | B10: # | D10: 2349 | E10: 2671 | G10: 2706 | H10: [3][5] and Q4 FY25 call [2]
A11: % of total ARR from > $50K partners | B11: % | D11: 0.57 | E11: 0.61 | G11: 0.63 | H11: [2][3][5]
A12: Dollar-based net revenue retention (cc) | B12: % | D12: 1.03 | E12: 1.03 | G12: 1.03 | H12: [2][3][5]
A13: Total revenue | B13: $mm | D13: 466 | E13: 511.43 | F13: 133.7 | G13: 138.2 | H13: [1][3][4][5]
A14: Subscription revenue | B14: $mm | D14: 459 | E14: 506.249 | F14: 132.5 | G14: 137.1 | H14: [1][3][4][5]
A15: Gross profit | B15: $mm | E15: 394.376 | H15: [1]
A16: Gross margin | B16: % | E16: =E15/E13 -> 0.7711241
A17: Sales and marketing expense | B17: $mm | E17: 163.163 | H17: [1]
A18: Research and development expense | B18: $mm | E18: 100.713 | H18: [1]
A19: General and administrative expense | B19: $mm | E19: 91.715 | H19: [1]
A20: Operating income | B20: $mm | E20: 36.789 | H20: [1]
A21: Adjusted EBITDA | B21: $mm | E21: 153.24 | F21: 36.7 | H21: [1][4]
A22: Adjusted EBITDA margin | B22: % | E22: =E21/E13 -> 0.29963045 | F22: =F21/F13 -> 0.27449514
A23: S&M as % of revenue | B23: % | E23: =E17/E13 -> 0.31903291
A24: Employees (approximate) | B24: # | G24: 2000 | H24: [5] 6% reduction = ~120 of ~2,000
A26: 2. FY2026 GUIDANCE - ORIGINAL (issued 18 Feb 2026, reaffirmed 6 May 2026)
A27: Metric | C27: Low | D27: High | E27: Midpoint | H27: Source
A28: Total ARR (Dec 31, 2026) | C28: 581 | D28: 586 | E28: =AVERAGE(C28:D28) -> 583.5 | H28: [1][4]
A29: Total revenue | C29: 554 | D29: 559 | E29: =AVERAGE(C29:D29) -> 556.5 | H29: [1][4]
A30: Adjusted EBITDA | C30: 167 | D30: 171 | E30: =AVERAGE(C30:D30) -> 169 | H30: [1][4]
A31: Free cash flow | C31: 114 | D31: 118 | E31: =AVERAGE(C31:D31) -> 116 | H31: [2]
A33: 3. FY2026 GUIDANCE - REVISED (issued 6 Aug 2026, with restructuring)
A34: Metric | C34: Low | D34: High | E34: Midpoint | F34: Cut vs original | H34: Source
A35: Total ARR (Dec 31, 2026) | C35: 562 | D35: 565 | E35: =AVERAGE(C35:D35) -> 563.5 | F35: =E35-E28 -> -20 | H35: [5]
A36: Total revenue | C36: 539 | D36: 542 | E36: =AVERAGE(C36:D36) -> 540.5 | F36: =E36-E29 -> -16 | H36: [5]
A37: Adjusted EBITDA | C37: 158 | D37: 161 | E37: =AVERAGE(C37:D37) -> 159.5 | F37: =E37-E30 -> -9.5 | H37: [5]
A38: Free cash flow | C38: 116 | D38: 120 | E38: =AVERAGE(C38:D38) -> 118 | F38: =E38-E31 -> 2 | H38: [5]
A40: Management commentary on the ARR guidance cut
A41: - Q2 FY2026 renewal cohort, the largest of the year, landed in the mid-80% range against a projected high-80% range in UEM and EDR [5]
A42: - EDR pricing pressure: partners retaining at lower price points or migrating to competitors [5]
A43: - Chief Revenue Officer transition (Russell Rosa, started July 2026) [5]
A44: - FX: approximately $5M of ARR impact [5]
...

Sheet ARR Bridge
A1: N-able, Inc. (NASDAQ: NABL) | SaaS Go-to-Market Metrics and Capacity Model
A2: Tab 4 | ARR Bridge - FY2025 decomposition and FY2026 requirement
A3: $ in millions unless noted
A5: 1. FY2025 ARR BRIDGE
A6: N-able does not disclose churn, expansion, or new-logo ARR. This bridge estimates each using reported ARR growth and NRR, plus a 90% GRR assumption
B8: FY2025A
A9: Beginning ARR (Dec 31, 2024) | B9: =Actuals!D7 -> 482
A10: Gross revenue retention (GRR) assumption | B10: =Assumptions!$B$23 -> 0.9
A11: Dollar-based net revenue retention, reported | B11: =Actuals!E12 -> 1.03
A12: ARR growth, constant currency, reported | B12: =Actuals!E9 -> 0.077
A14: (-) Gross churn and downgrade ARR | B14: =-B9*(1-B10) -> -48.2 | G14: beginning ARR x (1 - GRR)
A15: (+) Expansion and upsell ARR | B15: =B9*B11-(B9+B14) -> 62.66 | G15: net retained base less surviving base
A16: (+) New logo ARR | B16: =B9*(1+B12)-B9*B11 -> 22.654 | G16: cc ending ARR less net retained base
A17: (+/-) Implied FX impact | B17: =Actuals!E7-B9*(1+B12) -> 20.586 | G17: reported ending less cc ending
A18: Ending ARR (Dec 31, 2025) | B18: =B9+SUM(B14:B17) -> 539.7
A19: Reported ending ARR | B19: =Actuals!E7 -> 539.7
A20: Check (must equal zero) | B20: =B18-B19 -> 0
A22: Motion contribution
A23: Gross new ARR (new logo + expansion) | B23: =B15+B16 -> 85.314
A24: Net new ARR, constant currency | B24: =B14+B15+B16 -> 37.114
A25: New logo as % of gross new ARR | B25: =B16/B23 -> 0.26553672
A26: Expansion as % of gross new ARR | B26: =B15/B23 -> 0.73446328
A27: Gross churn as % of beginning ARR | B27: =-B14/B9 -> 0.1
A28: Expansion rate (% of beginning ARR) | B28: =B15/B9 -> 0.13
A29: New logo rate (% of beginning ARR) | B29: =B16/B9 -> 0.047
A31: 2. FY2026 REQUIREMENT - BACK-SOLVE AGAINST ORIGINAL GUIDANCE ($581M - $586M)
B32: Guidance low | C32: Guidance mid | D32: Guidance high
A33: Target ending ARR (Dec 31, 2026) | B33: =Actuals!C28 -> 581 | C33: =Actuals!E28 -> 583.5 | D33: =Actuals!D28 -> 586
A34: Beginning ARR (Dec 31, 2025) | B34: =$B$18 -> 539.7 | C34: =$B$18 -> 539.7 | D34: =$B$18 -> 539.7
A35: (+/-) Assumed FX impact | B35: =Assumptions!$B$19 -> 0 | C35: =Assumptions!$B$19 -> 0 | D35: =Assumptions!$B$19 -> 0
A36: Required constant-currency ending ARR | B36: =B33-B35 -> 581 | C36: =C33-C35 -> 583.5 | D36: =D33-D35 -> 586
A37: Gross revenue retention assumption, FY2026E | B37: =Assumptions!$B$16 -> 0.9 | C37: =Assumptions!$B$16 -> 0.9 | D37: =Assumptions!$B$16 -> 0.9
A38: (-) Gross churn and downgrade ARR | B38: =-B34*(1-B37) -> -53.97 | C38: =-C34*(1-C37) -> -53.97 | D38: =-D34*(1-D37) -> -53.97
A39: Required gross new ARR (new logo + expansion) | B39: =B36-B34-B38 -> 95.27 | C39: =C36-C34-C38 -> 97.77 | D39: =D36-D34-D38 -> 100.27
A41: Expansion ARR at FY2025 rate + scenario uplift | B41: =B34*($B$28+Assumptions!$B$18) -> 70.161 | C41: =C34*($B$28+Assumptions!$B$18) -> 70.161 | D41: =D34*($B$28+Assumptions!$B$18) -> 70.161 | G41: expansion held at the FY2025 rate
A42: Required new logo ARR (plug) | B42: =B39-B41 -> 25.109 | C42: =C39-C41 -> 27.609 | D42: =D39-D41 -> 30.109
A43: Required new logo growth vs FY2025 | B43: =B42/$B$16-1 -> 0.10836938 | C43: =C42/$B$16-1 -> 0.21872517 | D43: =D42/$B$16-1 -> 0.32908096
A44: Implied net revenue retention | B44: =(B34+B41+B38)/B34 -> 1.03 | C44: =(C34+C41+C38)/C34 -> 1.03 | D44: =(D34+D41+D38)/D34 -> 1.03 | G44: same 103% as FY2024-25
A45: Required gross new ARR growth vs FY2025 | B45: =B39/$B$23-1 -> 0.11669831 | C45: =C39/$B$23-1 -> 0.14600183 | D45: =D39/$B$23-1 -> 0.17530534
A47: 3. THE SAME BACK-SOLVE AGAINST REVISED GUIDANCE ($562M - $565M, issued 6 Aug 2026)
...

Sheet Segmentation
A1: N-able, Inc. (NASDAQ: NABL) | SaaS Go-to-Market Metrics and Capacity Model
A2: Tab 5 | Customer Segmentation - the $50K+ cohort versus the long tail
A3: $ in millions unless noted
A5: 1. COHORT SPLIT
A6: Metric | B6: FY2024A | C6: FY2025A | D6: Q2 FY2026A
A7: Total ARR | B7: =Actuals!D7 -> 482 | C7: =Actuals!E7 -> 539.7 | D7: =Actuals!G7 -> 544.5
A8: Partners with ARR > $50,000 | B8: =Actuals!D10 -> 2349 | C8: =Actuals!E10 -> 2671 | D8: =Actuals!G10 -> 2706
A9: % of total ARR from > $50K partners | B9: =Actuals!D11 -> 0.57 | C9: =Actuals!E11 -> 0.61 | D9: =Actuals!G11 -> 0.63
A11: ARR from > $50K partners | B11: =B7*B9 -> 274.74 | C11: =C7*C9 -> 329.217 | D11: =D7*D9 -> 343.035
A12: ARR from < $50K long tail | B12: =B7-B11 -> 207.26 | C12: =C7-C11 -> 210.483 | D12: =D7-D11 -> 201.465
A13: Average ARR per > $50K partner ($000) | B13: =B11/B8*1000 -> 116.96041 | C13: =C11/C8*1000 -> 123.25608 | D13: =D11/D8*1000 -> 126.76829
A15: YoY growth - total ARR | C15: =C7/B7-1 -> 0.11970954
A16: YoY growth - > $50K cohort ARR | C16: =C11/B11-1 -> 0.19828565
A17: YoY growth - long tail ARR | C17: =C12/B12-1 -> 0.015550516
A18: YoY growth - > $50K partner count | C18: =C8/B8-1 -> 0.13707961
A19: YoY growth - average ARR per large partner | C19: =C13/B13-1 -> 0.053827404
A21: Share of FY2025 ARR growth from > $50K cohort | C21: =(C11-B11)/(C7-B7) -> 0.94414211
A22: Long tail ARR change, FY2024 to FY2025 ($mm) | C22: =C12-B12 -> 3.223
A23: Long tail ARR change, FY2025 to Q2 FY2026 ($mm) | D23: =D12-C12 -> -9.018
A25: 2. WHY THE EXPANSION ASSUMPTION IS SENSITIVE
A26: 1. The >$50K cohort generated 94.4% of FY2025 ARR growth, raising its share of ARR from 57% to 61%.
A27: 2. Long-tail ARR grew only $3.2M in FY2025 and fell $9.0M by Q2 FY2026.
A28: 3. Holding the FY2025 expansion rate therefore assumes continued strength in the >$50K cohort.
A30: 3. ARR BY PARTNER COHORT

Sheet GTM Capacity
A1: N-able, Inc. (NASDAQ: NABL) | SaaS Go-to-Market Metrics and Capacity Model
A2: Tab 6 | Go-to-Market Capacity - productivity, ramp, headcount and cost
A3: $ in millions unless noted. Read top down: what a rep produced in FY2025, what the FY2026 plan needed, and whether the hiring schedule gets there
A5: 1. FY2025 PRODUCTIVITY CALIBRATION
A6: Total sales and marketing expense, FY2025 | B6: =Actuals!E17 -> 163.163
A7: Quota-carrying compensation as % of S&M | B7: =Assumptions!$B$26 -> 0.4
A8: Quota-carrying cost pool | B8: =B6*B7 -> 65.2652
A9: Fully loaded cost per quota-carrying rep ($000) | B9: =Assumptions!$B$27 -> 235
A10: Implied average quota-carrying reps ("QCRs"), FY2025 | B10: =B8/(B9/1000) -> 277.72426 | K10: Implied from reported S&M using modeled rep-cost assumptions.
A11: Gross new ARR delivered, FY2025 | B11: ='ARR Bridge'!B23 -> 85.314
A12: Achieved productivity per average QCR ($mm) | B12: =B11/B10 -> 0.30718959
A13: FY2025 quota attainment | B13: =Assumptions!$B$28 -> 0.85
A14: Implied quota per fully-ramped QCR ($mm) | B14: =B12/B13 -> 0.36139952
A15: S&M as % of revenue, FY2025 | B15: =Actuals!E23 -> 0.31903291
A17: 2. FY2026 CAPACITY REQUIREMENT (sized against the original $581M - $586M guidance)
A18: Required gross new ARR, guidance low | B18: ='ARR Bridge'!B39 -> 95.27
A19: Required gross new ARR, guidance midpoint | B19: ='ARR Bridge'!C39 -> 97.77 | K19: capacity is sized off this
A20: Required gross new ARR, guidance high | B20: ='ARR Bridge'!D39 -> 100.27
A21: Quota per fully-ramped QCR, FY2026 | B21: =B14*(1+Assumptions!$B$35) -> 0.3722415
A22: Quota attainment, FY2026 (scenario) | B22: =Assumptions!$B$20 -> 0.85
A23: Productivity per ramped QCR, FY2026 ($mm) | B23: =B21*B22 -> 0.31640528
A24: Required ramped-equivalent QCR-years | B24: =B19/B23 -> 309.00243
A25: Beginning QCR headcount (Jan 1, 2026) | B25: =B10*Assumptions!$B$29 -> 288.83323
A26: Capacity gap at zero hiring (QCR-years) | B26: =B24-B25 -> 20.169206
A27: Required pipeline coverage ratio | B27: =Assumptions!$B$34 -> 3.5
A28: Required qualified pipeline, FY2026 | B28: =B19*B27 -> 342.195 | K28: worth reconciling against actual pipeline before the plan is signed, not after
A30: 3. MONTHLY HIRING AND RAMP SCHEDULE, FY2026
A31: Annual quota-carrying hires (input) | B31: 96 | K31: change this cell and everything below reflows
A32: Monthly hires (evenly phased) | B32: =$B$31/12 -> 8
A34: Month | B34: New hires | C34: Attrition | D34: Ending QCR headcount | E34: Fully ramped from FY26 hires | F34: Partially ramped from FY26 hires | G34: Ramped-equiv. FTE | H34: Monthly capacity ($mm) | I34: Cumulative ($mm)
A35: 1 | B35: =$B$32 -> 8 | C35: =-$B$25*Assumptions!$B$33/12 -> -4.3324984 | D35: =$B$25+B35+C35 -> 292.50073 | E35: =SUMIFS($B$35:$B$46,$A$35:$A$46,"<="&A35-6) -> 0 | F35: =Assumptions!$B$31*SUMIFS($B$35:$B$46,$A$35:$A$46,">="&A35-5,$A$35:$A$46,"<="&A35-3) -> 0 | G35: =$B$25+SUM($C$35:C35)+E35+F35 -> 284.50073 | H35: =G35*$B$23/12 -> 7.501461 | I35: =H35 -> 7.501461
A36: 2 | B36: =$B$32 -> 8 | C36: =-D35*Assumptions!$B$33/12 -> -4.3875109 | D36: =D35+B36+C36 -> 296.11322 | E36: =SUMIFS($B$35:$B$46,$A$35:$A$46,"<="&A36-6) -> 0 | F36: =Assumptions!$B$31*SUMIFS($B$35:$B$46,$A$35:$A$46,">="&A36-5,$A$35:$A$46,"<="&A36-3) -> 0 | G36: =$B$25+SUM($C$35:C36)+E36+F36 -> 280.11322 | H36: =G36*$B$23/12 -> 7.385775 | I36: =I35+H36 -> 14.887236
A37: 3 | B37: =$B$32 -> 8 | C37: =-D36*Assumptions!$B$33/12 -> -4.4416982 | D37: =D36+B37+C37 -> 299.67152 | E37: =SUMIFS($B$35:$B$46,$A$35:$A$46,"<="&A37-6) -> 0 | F37: =Assumptions!$B$31*SUMIFS($B$35:$B$46,$A$35:$A$46,">="&A37-5,$A$35:$A$46,"<="&A37-3) -> 0 | G37: =$B$25+SUM($C$35:C37)+E37+F37 -> 275.67152 | H37: =G37*$B$23/12 -> 7.2686603 | I37: =I36+H37 -> 22.155896
A38: 4 | B38: =$B$32 -> 8 | C38: =-D37*Assumptions!$B$33/12 -> -4.4950728 | D38: =D37+B38+C38 -> 303.17645 | E38: =SUMIFS($B$35:$B$46,$A$35:$A$46,"<="&A38-6) -> 0 | F38: =Assumptions!$B$31*SUMIFS($B$35:$B$46,$A$35:$A$46,">="&A38-5,$A$35:$A$46,"<="&A38-3) -> 4 | G38: =$B$25+SUM($C$35:C38)+E38+F38 -> 275.17645 | H38: =G38*$B$23/12 -> 7.2556066 | I38: =I37+H38 -> 29.411503
A39: 5 | B39: =$B$32 -> 8 | C39: =-D38*Assumptions!$B$33/12 -> -4.5476467 | D39: =D38+B39+C39 -> 306.6288 | E39: =SUMIFS($B$35:$B$46,$A$35:$A$46,"<="&A39-6) -> 0 | F39: =Assumptions!$B$31*SUMIFS($B$35:$B$46,$A$35:$A$46,">="&A39-5,$A$35:$A$46,"<="&A39-3) -> 8 | G39: =$B$25+SUM($C$35:C39)+E39+F39 -> 274.6288 | H39: =G39*$B$23/12 -> 7.2411668 | I39: =I38+H39 -> 36.65267
A40: 6 | B40: =$B$32 -> 8 | C40: =-D39*Assumptions!$B$33/12 -> -4.599432 | D40: =D39+B40+C40 -> 310.02937 | E40: =SUMIFS($B$35:$B$46,$A$35:$A$46,"<="&A40-6) -> 0 | F40: =Assumptions!$B$31*SUMIFS($B$35:$B$46,$A$35:$A$46,">="&A40-5,$A$35:$A$46,"<="&A40-3) -> 12 | G40: =$B$25+SUM($C$35:C40)+E40+F40 -> 274.02937 | H40: =G40*$B$23/12 -> 7.2253615 | I40: =I39+H40 -> 43.878031
A41: 7 | B41: =$B$32 -> 8 | C41: =-D40*Assumptions!$B$33/12 -> -4.6504405 | D41: =D40+B41+C41 -> 313.37893 | E41: =SUMIFS($B$35:$B$46,$A$35:$A$46,"<="&A41-6) -> 8 | F41: =Assumptions!$B$31*SUMIFS($B$35:$B$46,$A$35:$A$46,">="&A41-5,$A$35:$A$46,"<="&A41-3) -> 12 | G41: =$B$25+SUM($C$35:C41)+E41+F41 -> 277.37893 | H41: =G41*$B$23/12 -> 7.3136797 | I41: =I40+H41 -> 51.191711
A42: 8 | B42: =$B$32 -> 8 | C42: =-D41*Assumptions!$B$33/12 -> -4.7006839 | D42: =D41+B42+C42 -> 316.67824 | E42: =SUMIFS($B$35:$B$46,$A$35:$A$46,"<="&A42-6) -> 16 | F42: =Assumptions!$B$31*SUMIFS($B$35:$B$46,$A$35:$A$46,">="&A42-5,$A$35:$A$46,"<="&A42-3) -> 12 | G42: =$B$25+SUM($C$35:C42)+E42+F42 -> 280.67824 | H42: =G42*$B$23/12 -> 7.4006731 | I42: =I41+H42 -> 58.592384
A43: 9 | B43: =$B$32 -> 8 | C43: =-D42*Assumptions!$B$33/12 -> -4.7501736 | D43: =D42+B43+C43 -> 319.92807 | E43: =SUMIFS($B$35:$B$46,$A$35:$A$46,"<="&A43-6) -> 24 | F43: =Assumptions!$B$31*SUMIFS($B$35:$B$46,$A$35:$A$46,">="&A43-5,$A$35:$A$46,"<="&A43-3) -> 12 | G43: =$B$25+SUM($C$35:C43)+E43+F43 -> 283.92807 | H43: =G43*$B$23/12 -> 7.4863616 | I43: =I42+H43 -> 66.078745
A44: 10 | B44: =$B$32 -> 8 | C44: =-D43*Assumptions!$B$33/12 -> -4.798921 | D44: =D43+B44+C44 -> 323.12915 | E44: =SUMIFS($B$35:$B$46,$A$35:$A$46,"<="&A44-6) -> 32 | F44: =Assumptions!$B$31*SUMIFS($B$35:$B$46,$A$35:$A$46,">="&A44-5,$A$35:$A$46,"<="&A44-3) -> 12 | G44: =$B$25+SUM($C$35:C44)+E44+F44 -> 287.12915 | H44: =G44*$B$23/12 -> 7.5707648 | I44: =I43+H44 -> 73.64951
...

Sheet Scenarios
A1: N-able, Inc. (NASDAQ: NABL) | SaaS Go-to-Market Metrics and Capacity Model
A2: Tab 7 | Scenario Analysis - forward-modeled ARR against the guidance band
A3: $ in millions unless noted
A5: Each case applies its own retention, expansion, new-logo, and FX assumptions. ARR outputs are not capped by the GTM capacity schedule
A6: 1. FORWARD-MODELED FY2026 ENDING ARR
A7: Driver / output | B7: Downside | C7: Base | D7: Upside
A8: Gross revenue retention (GRR) | B8: =INDEX(Assumptions!$C$11:$C$13,1) -> 0.888 | C8: =INDEX(Assumptions!$C$11:$C$13,2) -> 0.9 | D8: =INDEX(Assumptions!$C$11:$C$13,3) -> 0.915
A9: New logo ARR growth vs FY2025 | B9: =INDEX(Assumptions!$D$11:$D$13,1) -> -0.05 | C9: =INDEX(Assumptions!$D$11:$D$13,2) -> 0.08 | D9: =INDEX(Assumptions!$D$11:$D$13,3) -> 0.2
A10: Expansion rate uplift vs FY2025 | B10: =INDEX(Assumptions!$E$11:$E$13,1) -> -0.012 | C10: =INDEX(Assumptions!$E$11:$E$13,2) -> 0 | D10: =INDEX(Assumptions!$E$11:$E$13,3) -> 0.02
A11: FX impact on ending ARR | B11: =INDEX(Assumptions!$F$11:$F$13,1) -> -5 | C11: =INDEX(Assumptions!$F$11:$F$13,2) -> 0 | D11: =INDEX(Assumptions!$F$11:$F$13,3) -> 5
A12: Quota attainment (used in GTM Capacity only) | B12: =INDEX(Assumptions!$G$11:$G$13,1) -> 0.78 | C12: =INDEX(Assumptions!$G$11:$G$13,2) -> 0.85 | D12: =INDEX(Assumptions!$G$11:$G$13,3) -> 0.92
A14: Beginning ARR (Dec 31, 2025) | B14: ='ARR Bridge'!$B$18 -> 539.7 | C14: ='ARR Bridge'!$B$18 -> 539.7 | D14: ='ARR Bridge'!$B$18 -> 539.7
A15: (-) Gross churn and downgrade | B15: =-B14*(1-B8) -> -60.4464 | C15: =-C14*(1-C8) -> -53.97 | D15: =-D14*(1-D8) -> -45.8745
A16: (+) Expansion and upsell | B16: =B14*('ARR Bridge'!$B$28+B10) -> 63.6846 | C16: =C14*('ARR Bridge'!$B$28+C10) -> 70.161 | D16: =D14*('ARR Bridge'!$B$28+D10) -> 80.955
A17: (+) New logo | B17: ='ARR Bridge'!$B$16*(1+B9) -> 21.5213 | C17: ='ARR Bridge'!$B$16*(1+C9) -> 24.46632 | D17: ='ARR Bridge'!$B$16*(1+D9) -> 27.1848
A18: (+/-) Implied FX impact | B18: =B11 -> -5 | C18: =C11 -> 0 | D18: =D11 -> 5
A19: Ending ARR (Dec 31, 2026) | B19: =B14+SUM(B15:B18) -> 559.4595 | C19: =C14+SUM(C15:C18) -> 580.35732 | D19: =D14+SUM(D15:D18) -> 606.9653
A20: Implied ARR growth | B20: =B19/B14-1 -> 0.036612007 | C20: =C19/C14-1 -> 0.075333185 | D20: =D19/D14-1 -> 0.12463461
A21: Implied net revenue retention | B21: =(B14+B16+B15)/B14 -> 1.006 | C21: =(C14+C16+C15)/C14 -> 1.03 | D21: =(D14+D16+D15)/D14 -> 1.065
A23: 2. TEST AGAINST GUIDANCE
A24: Original guidance low | B24: =Actuals!$C$28 -> 581 | C24: =Actuals!$C$28 -> 581 | D24: =Actuals!$C$28 -> 581
A25: Original guidance high | B25: =Actuals!$D$28 -> 586 | C25: =Actuals!$D$28 -> 586 | D25: =Actuals!$D$28 -> 586
A26: Surplus / (shortfall) vs original low | B26: =B19-B24 -> -21.5405 | C26: =C19-C24 -> -0.64268 | D26: =D19-D24 -> 25.9653
A27: Clears original guidance? | B27: =IF(B19>=B24,"YES","NO") -> NO | C27: =IF(C19>=C24,"YES","NO") -> NO | D27: =IF(D19>=D24,"YES","NO") -> YES
A29: Revised guidance low (6 Aug 2026) | B29: =Actuals!$C$35 -> 562 | C29: =Actuals!$C$35 -> 562 | D29: =Actuals!$C$35 -> 562
A30: Surplus / (shortfall) vs revised low | B30: =B19-B29 -> -2.5405 | C30: =C19-C29 -> 18.35732 | D30: =D19-D29 -> 44.9653
A31: Clears revised guidance? | B31: =IF(B19>=B29,"YES","NO") -> NO | C31: =IF(C19>=C29,"YES","NO") -> YES | D31: =IF(D19>=D29,"YES","NO") -> YES
A33: 3. TWO-WAY SENSITIVITY - FY2026 ENDING ARR ($mm)
A34: Rows = gross revenue retention. Columns = new logo ARR growth vs FY2025. Expansion held at the FY2025 rate, FX at zero
A35: GRR \ New logo growth | B35: =Assumptions!B$38 -> -0.2 | C35: =Assumptions!C$38 -> -0.1 | D35: =Assumptions!D$38 -> 0 | E35: =Assumptions!E$38 -> 0.1 | F35: =Assumptions!F$38 -> 0.2
A36: =Assumptions!B$37 -> 0.87 | B36: =$B$14-$B$14*(1-$A36)+$B$14*'ARR Bridge'!$B$28+'ARR Bridge'!$B$16*(1+B$35) -> 557.8232 | C36: =$B$14-$B$14*(1-$A36)+$B$14*'ARR Bridge'!$B$28+'ARR Bridge'!$B$16*(1+C$35) -> 560.0886 | D36: =$B$14-$B$14*(1-$A36)+$B$14*'ARR Bridge'!$B$28+'ARR Bridge'!$B$16*(1+D$35) -> 562.354 | E36: =$B$14-$B$14*(1-$A36)+$B$14*'ARR Bridge'!$B$28+'ARR Bridge'!$B$16*(1+E$35) -> 564.6194 | F36: =$B$14-$B$14*(1-$A36)+$B$14*'ARR Bridge'!$B$28+'ARR Bridge'!$B$16*(1+F$35) -> 566.8848
A37: =Assumptions!C$37 -> 0.885 | B37: =$B$14-$B$14*(1-$A37)+$B$14*'ARR Bridge'!$B$28+'ARR Bridge'!$B$16*(1+B$35) -> 565.9187 | C37: =$B$14-$B$14*(1-$A37)+$B$14*'ARR Bridge'!$B$28+'ARR Bridge'!$B$16*(1+C$35) -> 568.1841 | D37: =$B$14-$B$14*(1-$A37)+$B$14*'ARR Bridge'!$B$28+'ARR Bridge'!$B$16*(1+D$35) -> 570.4495 | E37: =$B$14-$B$14*(1-$A37)+$B$14*'ARR Bridge'!$B$28+'ARR Bridge'!$B$16*(1+E$35) -> 572.7149 | F37: =$B$14-$B$14*(1-$A37)+$B$14*'ARR Bridge'!$B$28+'ARR Bridge'!$B$16*(1+F$35) -> 574.9803
A38: =Assumptions!D$37 -> 0.9 | B38: =$B$14-$B$14*(1-$A38)+$B$14*'ARR Bridge'!$B$28+'ARR Bridge'!$B$16*(1+B$35) -> 574.0142 | C38: =$B$14-$B$14*(1-$A38)+$B$14*'ARR Bridge'!$B$28+'ARR Bridge'!$B$16*(1+C$35) -> 576.2796 | D38: =$B$14-$B$14*(1-$A38)+$B$14*'ARR Bridge'!$B$28+'ARR Bridge'!$B$16*(1+D$35) -> 578.545 | E38: =$B$14-$B$14*(1-$A38)+$B$14*'ARR Bridge'!$B$28+'ARR Bridge'!$B$16*(1+E$35) -> 580.8104 | F38: =$B$14-$B$14*(1-$A38)+$B$14*'ARR Bridge'!$B$28+'ARR Bridge'!$B$16*(1+F$35) -> 583.0758
A39: =Assumptions!E$37 -> 0.915 | B39: =$B$14-$B$14*(1-$A39)+$B$14*'ARR Bridge'!$B$28+'ARR Bridge'!$B$16*(1+B$35) -> 582.1097 | C39: =$B$14-$B$14*(1-$A39)+$B$14*'ARR Bridge'!$B$28+'ARR Bridge'!$B$16*(1+C$35) -> 584.3751 | D39: =$B$14-$B$14*(1-$A39)+$B$14*'ARR Bridge'!$B$28+'ARR Bridge'!$B$16*(1+D$35) -> 586.6405 | E39: =$B$14-$B$14*(1-$A39)+$B$14*'ARR Bridge'!$B$28+'ARR Bridge'!$B$16*(1+E$35) -> 588.9059 | F39: =$B$14-$B$14*(1-$A39)+$B$14*'ARR Bridge'!$B$28+'ARR Bridge'!$B$16*(1+F$35) -> 591.1713
A40: =Assumptions!F$37 -> 0.93 | B40: =$B$14-$B$14*(1-$A40)+$B$14*'ARR Bridge'!$B$28+'ARR Bridge'!$B$16*(1+B$35) -> 590.2052 | C40: =$B$14-$B$14*(1-$A40)+$B$14*'ARR Bridge'!$B$28+'ARR Bridge'!$B$16*(1+C$35) -> 592.4706 | D40: =$B$14-$B$14*(1-$A40)+$B$14*'ARR Bridge'!$B$28+'ARR Bridge'!$B$16*(1+D$35) -> 594.736 | E40: =$B$14-$B$14*(1-$A40)+$B$14*'ARR Bridge'!$B$28+'ARR Bridge'!$B$16*(1+E$35) -> 597.0014 | F40: =$B$14-$B$14*(1-$A40)+$B$14*'ARR Bridge'!$B$28+'ARR Bridge'!$B$16*(1+F$35) -> 599.2668
A42: Green = clears the original $581M guidance floor. Red = falls below even the revised $562M floor. White = between the two.
A43: Retention matters most: at 90% GRR, only +20% new-logo growth clears the original floor; below 90%, even +20% does not
A44: 4. THE THREE CASES AGAINST BOTH FLOORS
A64: Chart data - guidance floors, drawn as flat lines across the three cases
A65: Original floor ($581M) | B65: =$B$24 -> 581 | C65: =$B$24 -> 581 | D65: =$B$24 -> 581
...
